# TODAY I LEARNED

## Learned

### Promise

Promise에 대해서는 Web Docs에 자세하게 설명되어 있습니다.
`https://developer.mozilla.org/ko/docs/Web/JavaScript/Reference/Global_Objects/Promise`

비동기적인 처리를 할 때  보통 callback으로 작성하게 되는데 이 경우, 콜백 헬과 같은 가독성 문제가 발생하고, 안쪽 scope일 수록 참조할 수 있는 바깥쪽 함수들이 점점 늘어나므로 실수할 가능성도 높아집니다.
그래서 이런 문제들 때문에 Promise나 async await를 이용하여 해결하게 됩니다.

#### catch에 영향을 미치는 catch의 순서

.catch는 순서에 영향을 받습니다. Promise chain상에서 catch에서 가장 가까이 있는 에러를 잡아줍니다.

Promise(reject) -> then -> catch의 경우

```javascript
new Promise((resolve, reject) => {
  console.log('Inside promise')
  reject(new Error('First reject'))
  resolve('First resolve')
})
  .then((value) => {
    console.log('Inside first then')
    console.log('value', value)
  })
  .catch((error) => {
    console.log('error', error)
  })
  
  // 실행결과
  // Error: First reject
```

Promise(reject) -> catch-> then의 경우

```javascript
new Promise((resolve, reject) => {
  console.log('Inside promise')
  reject(new Error('First reject'))
  resolve('First resolve')
})
  .catch((error) => {
    console.log('error', error)
  })
  .then((value) => { // resolve 된 결과값이 없기 때문에 undefined
    console.log('Inside first then')
    console.log('value', value)
  })
  
  // 실행결과
  // Error: First reject
  // Inside first then
  // value undefined
```

Promise는 resolve든 reject든 결정되고 난 후에 다시는 실행되지 않습니다.

#### reject와 resolve 둘 중 하나가 실행되고 난 이후 Promise 내부 상황

Javascript는 콜스택이 빌때까지 계속 실행되기 때문에 먼저 작성된 reject가 실행이 되더라도 reject 다음줄에 작성한 resolve도 실행될 것이라 예측해 볼 수 있겠지만 그렇지 않습니다.

```javascript
new Promise((resolve, reject) => {
  console.log('Inside promise')
  reject(new Error('First reject'))
  console.log('before resolve');
  resolve('First resolve')
  console.log('after resolve');
})
  .catch((error) => {
    console.log('error', error)
  })
  .then((value) => {
    console.log('Inside first then')
    console.log('value', value)
  })
  
  // 실행결과
  // Inside promise
  // before resolve
  // after resolve
  // Error: First reject
  // Inside first then
  // value undefined
```

위처럼 reject가 실행된 다음 줄부터 Promise안의 다른 console.log는 실행이 되지만 resolve는 실행되지 않습니다.
반대로 resolve와 reject를 바꿔서 실행하면, 역시 먼저 실행된 resolve만 실행되고 reject는 실행되지 않습니다.

```javascript
new Promise((resolve, reject) => {
  console.log('Inside promise')
  resolve('First resolve')
  console.log('before reject');
  reject(new Error('First reject'))
  console.log('after reject');
})
  .catch((error) => {
    console.log('error', error)
  })
  .then((value) => {
    console.log('Inside first then')
    console.log('value', value)
  })
  
  // 실행결과
  // Inside promise
  // before reject
  // after reject
  // Inside first then
  // value First resolve
```

즉, reject든 resolve든 둘 중에 먼저 실행되어 결정된 값으로 정해지고 결정된 이후에 실행된 reject나 resolve는 실행되지 않습니다.

#### Promise의 유용한 예

가장 예로 들기 쉬운 경우가 비동기 코드인 setTimeout입니다.

1. 비동기코드를 직렬로 연결

```javascript
new Promise((resolve, reject) => {
  console.log('Before timeout')
  setTimeout(() => {
    resolve(Math.random())
    console.log('After resolve')
  }, 1000)
})
  .then((value) => {
    console.log('then 1')
    console.log('value', value)
  })
  .then(() => {
    console.log('then 2')
  })
  .then(() => {
    console.log('then 3')
  })
// 실행 결과
// Before timeout
// After resolve
// then 1
// value 0.93425245
// then 2
// then 3
```

위 코드에서는 처음에 setTimeout을 사용해서 비동기 처리를 하는 것은 좋은데, 그 뒤에 이어서 작성한 then은 전부 동기적으로 실행되니 큰 의미가 없지 않냐고 생각할 수도 있겠습니다.

2. then에서 Promise를 return하기
then이 할 수 있는 특별한 일이 있습니다. then에서 promise를 return하면 다음 then에서 promise가 끝나기를 기다립니다.

좀 더 구체적인 예시.

```javascript
function returnPromiseForTimeout() {
  return new Promise((resolve) => {
    setTimeout(() => {
      resolve(Math.random())
    }, 1000)
  })
}

returnPromiseForTimeout()
  .then((value) => {
    console.log('1', value)
    return returnPromiseForTimeout()
  })
  .then((value) => {
    console.log('2', value)
    return returnPromiseForTimeout()
  })
  .then((value) => {
    console.log('3', value)
    return returnPromiseForTimeout()
  })
  .then((value) => {
    console.log('4', value)
  })
  
  // 실행 결과
  // 1 0.3445543
  // 2 0.5766575
  // 3 0.8657567
  // 4 0.6453434
```

이런식으로 Promise chain이 가능해집니다.
만약 위 코드를 Promise 없이 작성한다면 어떤 코드가 되었을까요? callback 형태의 callback지옥 모양이 되었을 것입니다.

아래는 위 코드를 Promise없이 작성한 코드.

```javascript
setTimeout(() => {
  const value = Math.random()
  console.log('1', value)
  setTimeout(() => {
    const value = Math.random()
    console.log('2', value)
    setTimeout(() => {
      const value = Math.random()
      console.log('3', value)
      setTimeout(() => {
        const value = Math.random()
        console.log('4', value)
      }, 1000)
    }, 1000)
  }, 1000)
}, 1000)
```

또는

```javascript
function bounceCode(callback) {
  setTimeout(() => {
    const value = Math.random()
    callback(value)
  }, 1000)
}

bounceCode((value) => {
  console.log('1', value)
  bounceCode((value) => {
    console.log('2', value)
    bounceCode((value) => {
      console.log('3', value)
      bounceCode((value) => {
        console.log('4', value)
      })
    })
  })
})
```

#### Node에서 제공하는 Promise 스타일의 API 예시

Node에서도 Promise 스타일의 API를 제공해줍니다.
예를 들어 .gitignore 파일을 읽는 코드를 작성시에 아래처럼 promise 스타일의 API를 사용할 수 있습니다.

```javascript
fs.promises.readFile('.gitignore').then((value) => console.log(value));
```

만약 Promise 스타일의 API를 제공하지 않았다면.. 아래 처럼 작성해야 될 것입니다.

```javascript
const fs = require('fs')

function readFileInPromise(fileName) {
  return new Promise((resolve, reject) => {
    fs.readFile('.gitignore', 'utf-8', (error, value) => {
      if (error) {
        reject(error)
      }
      resolve(value)
    })
  })
}

readFileInPromise('.gitignore').then((value) => console.log(value))
```

#### Promise와 async, await 키워드와의 관련성

- async함수 안에서 반환된 Promise에 await 키워드를 사용하여 Promise의 반환값을 기다릴 수 있습니다.
- async 함수는 결국 Promise를 돌려주는 함수입니다. async 함수는 항상 promise를 반환합니다. 만약 async 함수의 반환값이 명시적으로 promise가 아니라면 암묵적으로 promise로 감싸집니다.
예를 들어

```javascript
async function foo() {
        return 1
    }
```

위 코드는 아래와 같습니다.

```javascript
function foo() {
        return Promise.resolve(1)
    }
```

- async 함수의 본문은 0개 이상의 await 문으로 분할된 것으로 생각할 수 있습니다. 첫번째 await 문을 포함하는 최상위 코드는 동기적으로 실행됩니다. 따라서 await 문이 없는 async 함수는 동기적으로 실행됩니다. 하지만 await 문이 있다면 async 함수는 항상 비동기적으로 완료됩니다.
예를 들어

```javascript
    async function foo() {
        await 1
    }
```

위 코드는 아래와 같습니다.

```javascript
    function foo() {
        return Promise.resolve(1).then(() => undefined)
    }
```

##### 예시 코드

```javascript
function sleep(duration) {
  return new Promise((resolve) => {
    setTimeout(() => {
      resolve(undefined)
    }, duration)
  })
}

async function main() {
  console.log('first')
  await sleep(1000)
  console.log('second')
  await sleep(1000)
  console.log('third')
  await sleep(1000)
  console.log('finish!')
}

main()
// 실행 결과 (1초 마다 출력..)
// first
// second
// third
// finish!
```

##### async await 에서 에러 잡기

try catch block을 사용합니다.

```javascript
const fs = require('fs');

async function main() {
    try {
        const result = await fs.promises.readFile('.gitignore', 'utf-8');
        console.log(result);
    } catch (error) {
        console.log('error', error);
    }
}

main();
```

